2024-01-26 20:46:34.804657: W tensorflow/stream_executor/platform/default/dso_loader.cc:64] Could not load dynamic library 'libcudart.so.11.0'; dlerror: libcudart.so.11.0: cannot open shared object file: No such file or directory; LD_LIBRARY_PATH: /usr/lib64/mpich/lib:/home/vagrant/.local/lib
2024-01-26 20:46:34.804726: I tensorflow/stream_executor/cuda/cudart_stub.cc:29] Ignore above cudart dlerror if you do not have a GPU set up on your machine.
2024-01-26 20:46:34.905065: E tensorflow/stream_executor/cuda/cuda_blas.cc:2981] Unable to register cuBLAS factory: Attempting to register factory for plugin cuBLAS when one has already been registered
Traceback (most recent call last):
  File "/home/vagrant/.pyenv/versions/py3/bin/sirepo", line 33, in <module>
    sys.exit(load_entry_point('sirepo', 'console_scripts', 'sirepo')())
  File "/home/vagrant/src/radiasoft/sirepo/sirepo/sirepo_console.py", line 18, in main
    return pkcli.main("sirepo")
  File "/home/vagrant/src/radiasoft/pykern/pykern/pkcli/__init__.py", line 165, in main
    res = argh.dispatch(parser, argv=argv)
  File "/home/vagrant/.pyenv/versions/3.9.15/envs/py3/lib/python3.9/site-packages/argh/dispatching.py", line 179, in dispatch
    for line in lines:
  File "/home/vagrant/.pyenv/versions/3.9.15/envs/py3/lib/python3.9/site-packages/argh/dispatching.py", line 290, in _execute_command
    for line in result:
  File "/home/vagrant/.pyenv/versions/3.9.15/envs/py3/lib/python3.9/site-packages/argh/dispatching.py", line 273, in _call
    result = function(*positional, **keywords)
  File "/home/vagrant/src/radiasoft/sirepo/sirepo/pkcli/activait.py", line 23, in run_background
    template_common.exec_parameters()
  File "/home/vagrant/src/radiasoft/sirepo/sirepo/template/template_common.py", line 420, in exec_parameters
    return pkrunpy.run_path_as_module(path or PARAMETERS_PYTHON_FILE)
  File "/home/vagrant/src/radiasoft/pykern/pykern/pkrunpy.py", line 28, in run_path_as_module
    exec(code, m.__dict__)
  File "parameters.py", line 8, in <module>
    import keras
  File "/home/vagrant/.pyenv/versions/3.9.15/envs/py3/lib/python3.9/site-packages/keras/__init__.py", line 20, in <module>
    from keras import distribute
  File "/home/vagrant/.pyenv/versions/3.9.15/envs/py3/lib/python3.9/site-packages/keras/distribute/__init__.py", line 18, in <module>
    from keras.distribute import sidecar_evaluator
  File "/home/vagrant/.pyenv/versions/3.9.15/envs/py3/lib/python3.9/site-packages/keras/distribute/sidecar_evaluator.py", line 17, in <module>
    import tensorflow.compat.v2 as tf
  File "/home/vagrant/.pyenv/versions/3.9.15/envs/py3/lib/python3.9/site-packages/tensorflow/__init__.py", line 37, in <module>
    from tensorflow.python.tools import module_util as _module_util
  File "/home/vagrant/.pyenv/versions/3.9.15/envs/py3/lib/python3.9/site-packages/tensorflow/python/__init__.py", line 37, in <module>
    from tensorflow.python.eager import context
  File "/home/vagrant/.pyenv/versions/3.9.15/envs/py3/lib/python3.9/site-packages/tensorflow/python/eager/context.py", line 29, in <module>
    from tensorflow.core.framework import function_pb2
  File "/home/vagrant/.pyenv/versions/3.9.15/envs/py3/lib/python3.9/site-packages/tensorflow/core/framework/function_pb2.py", line 16, in <module>
    from tensorflow.core.framework import attr_value_pb2 as tensorflow_dot_core_dot_framework_dot_attr__value__pb2
  File "/home/vagrant/.pyenv/versions/3.9.15/envs/py3/lib/python3.9/site-packages/tensorflow/core/framework/attr_value_pb2.py", line 16, in <module>
    from tensorflow.core.framework import tensor_pb2 as tensorflow_dot_core_dot_framework_dot_tensor__pb2
  File "/home/vagrant/.pyenv/versions/3.9.15/envs/py3/lib/python3.9/site-packages/tensorflow/core/framework/tensor_pb2.py", line 16, in <module>
    from tensorflow.core.framework import resource_handle_pb2 as tensorflow_dot_core_dot_framework_dot_resource__handle__pb2
  File "/home/vagrant/.pyenv/versions/3.9.15/envs/py3/lib/python3.9/site-packages/tensorflow/core/framework/resource_handle_pb2.py", line 16, in <module>
    from tensorflow.core.framework import tensor_shape_pb2 as tensorflow_dot_core_dot_framework_dot_tensor__shape__pb2
  File "/home/vagrant/.pyenv/versions/3.9.15/envs/py3/lib/python3.9/site-packages/tensorflow/core/framework/tensor_shape_pb2.py", line 36, in <module>
    _descriptor.FieldDescriptor(
  File "/home/vagrant/.pyenv/versions/3.9.15/envs/py3/lib/python3.9/site-packages/google/protobuf/descriptor.py", line 553, in __new__
    _message.Message._CheckCalledFromGeneratedFile()
TypeError: Descriptors cannot be created directly.
If this call came from a _pb2.py file, your generated code is out of date and must be regenerated with protoc >= 3.19.0.
If you cannot immediately regenerate your protos, some other possible workarounds are:
 1. Downgrade the protobuf package to 3.20.x or lower.
 2. Set PROTOCOL_BUFFERS_PYTHON_IMPLEMENTATION=python (but this will use pure-Python parsing and will be much slower).

More information: https://developers.google.com/protocol-buffers/docs/news/2022-05-06#python-updates
